Workbook

Sheet Instructions
A1: HOU6 TOTE TRACKING TOOL — INSTRUCTIONS
A3: OVERVIEW
A4: This workbook tracks tote inventory across all 5 floors of HOU6, calculates demand,
A5: and provides prescriptions for pallet movement. It has 4 main sheets plus this one.
A7: SHEET GUIDE
A8: Sheet Name | B8: Purpose
A9: Tote Count Entry | B9: Where you enter tote counts by floor and area (Stacks & Pallets)
A10: Building Overview | B10: Auto-generated summary of all floors with surplus/deficit and prescriptions
A11: Demand Calculator | B11: Set picker count, pick rate, and shift length to calculate tote demand
A12: Historical Data | B12: Tracks daily snapshots of tote counts for trend analysis
A13: Quick View | B13: Simplified dashboard — at-a-glance status, floor prescriptions, and action steps
A14: STEP-BY-STEP: DAILY TOTE COUNT
A16: Step 1: Update Demand Inputs (if needed)
A17: Go to the Demand Calculator sheet.
A18: Update the yellow cells if staffing or rates have changed:
A19: • Number of Active Pickers (total building headcount)
A20: • Pick Rate / UPH per picker
A21: • Avg Units Per Tote
A22: • Shift Length in hours
A23: These values drive the building-wide demand calculation.
A25: Then scroll down to the PER-FLOOR HEADCOUNT section:
A26: • Enter the headcount for each floor (2nd through 5th) in the yellow cells.
A27: • 1st Floor uses the building-wide demand total from the top section.
... A79: KEY CONSTANTS
A80: Value | B80: Meaning
A81: 11 | B81: Totes per stack
A82: 6 | B82: Stacks per pallet
A83: 66 | B83: Totes per pallet (11 × 6)
A85: HISTORICAL DATA — HOW IT WORKS
A87: Rows 2-6 contain LIVE FORMULAS that always show current Tote Count Entry values.
A88: They auto-populate: Date, Day of Week, Floor, area totals, and Stacks/Pallets breakdowns.
A90: Because these are live formulas, they update every time you change the Tote Count Entry.
A91: To keep a permanent record, you MUST paste-as-values before entering new counts.
A93: Historical Data Columns:
A94: A: Date J: EAST Pallets P: SOUTH Pallets
A95: B: Day of Week K: EAST Stacks Q: SOUTH Stacks
A96: C: Floor L: NORTH Pallets R: VDT Pallets
A97: D: EAST (total totes) M: NORTH Stacks S: VDT Stacks
A98: E: WEST (total totes) N: WEST Pallets T: Damaged Pallets
A99: F: NORTH (total totes) O: WEST Stacks U: Damaged Stacks
...

Sheet Tote Count Entry
B1: HOU6 | C1: Tote Count for HOU6!
C2: =TODAY() -> 46292
B4: Floor | C4: Total Totes in Facility | D4: Total Usable (Cln + Vir D) | E4: EAST/IB | F4: WEST/Trans Ship | G4: North/Pack | H4: South AFE/Dock | I4: Virtually Dirty | J4: Damaged Totes
B5: 1st | C5: =D5+J5 -> 0 | D5: =SUM(E5:I5) -> 0 | E5: =S44+T44 -> 0 | F5: =U44+V44 -> 0 | G5: =W44+X44 -> 0 | H5: =Y44+Z44 -> 0 | I5: =AB44+AC44 -> 0 | J5: =AD44+AE44 -> 0
B6: 2nd | C6: =D6+J6 -> 0 | D6: =SUM(E6:I6) -> 0 | E6: =S77+T77 -> 0 | F6: =U77+V77 -> 0 | G6: =W77+X77 -> 0 | H6: =Y77+Z77 -> 0 | I6: =AB77+AC77 -> 0 | J6: =AD77+AE77 -> 0
B7: 3rd | C7: =D7+J7 -> 0 | D7: =SUM(E7:I7) -> 0 | E7: =S109+T109 -> 0 | F7: =U109+V109 -> 0 | G7: =W109+X109 -> 0 | H7: =Y109+Z109 -> 0 | I7: =AB109+AC109 -> 0 | J7: =AD109+AE109 -> 0
B8: 4th | C8: =D8+J8 -> 0 | D8: =SUM(E8:I8) -> 0 | E8: =S141+T141 -> 0 | F8: =U141+V141 -> 0 | G8: =W141+X141 -> 0 | H8: =Y141+Z141 -> 0 | I8: =AB141+AC141 -> 0 | J8: =AD141+AE141 -> 0
B9: 5th | C9: =D9+J9 -> 0 | D9: =SUM(E9:I9) -> 0 | E9: =S173+T173 -> 0 | F9: =U173+V173 -> 0 | G9: =W173+X173 -> 0 | H9: =Y173+Z173 -> 0 | I9: =AB173+AC173 -> 0 | J9: =AD173+AE173 -> 0
B10: Building Total | C10: =SUM(C5:C9) -> 0 | D10: =SUM(D5:D9) -> 0 | E10: =SUM(E5:E9) -> 0 | F10: =SUM(F5:F9) -> 0 | G10: =SUM(G5:G9) -> 0 | H10: =SUM(H5:H9) -> 0 | I10: =SUM(I5:I9) -> 0 | J10: =SUM(J5:J9) -> 0
S13: 1st Floor
S14: East | U14: Transhipment | W14: PACK | Y14: AFE/Tote Wash | AB14: Virtually Dirty Totes | AD14: Damaged Totes
S15: 1 | U15: 2 | W15: 3 | Y15: 4 | AB15: First Floor | AD15: First Floor
S16: S | T16: P | U16: S | V16: P | W16: S | X16: P | Y16: S | Z16: P | AB16: S | AC16: P | AD16: S | AE16: P
S17: 0 | T17: 0 | U17: 0 | V17: 0 | W17: 0 | X17: 0 | Y17: 0 | Z17: 0 | AB17: 0 | AC17: 0 | AD17: 0 | AE17: 0
S18: 0 | T18: 0 | U18: 0 | V18: 0 | W18: 0 | X18: 0 | Y18: 0 | Z18: 0 | AB18: 0 | AC18: 0 | AD18: 0 | AE18: 0
S19: 0 | T19: 0 | U19: 0 | V19: 0 | W19: 0 | X19: 0 | Y19: 0 | Z19: 0 | AB19: 0 | AC19: 0 | AD19: 0 | AE19: 0
S20: 0 | T20: 0 | U20: 0 | V20: 0 | W20: 0 | X20: 0 | Y20: 0 | Z20: 0 | AB20: 0 | AC20: 0 | AD20: 0 | AE20: 0
S21: 0 | T21: 0 | U21: 0 | V21: 0 | W21: 0 | X21: 0 | Y21: 0 | Z21: 0 | AB21: 0 | AC21: 0 | AD21: 0 | AE21: 0
S22: 0 | T22: 0 | U22: 0 | V22: 0 | W22: 0 | X22: 0 | Y22: 0 | Z22: 0 | AB22: 0 | AC22: 0 | AD22: 0 | AE22: 0
S23: 0 | T23: 0 | U23: 0 | V23: 0 | W23: 0 | X23: 0 | Y23: 0 | Z23: 0 | AB23: 0 | AC23: 0 | AD23: 0 | AE23: 0
S24: 0 | T24: 0 | U24: 0 | V24: 0 | W24: 0 | X24: 0 | Y24: 0 | Z24: 0 | AB24: 0 | AC24: 0 | AD24: 0 | AE24: 0
S25: 0 | T25: 0 | U25: 0 | V25: 0 | W25: 0 | X25: 0 | Y25: 0 | Z25: 0 | AB25: 0 | AC25: 0 | AD25: 0 | AE25: 0
S26: 0 | T26: 0 | U26: 0 | V26: 0 | W26: 0 | X26: 0 | Y26: 0 | Z26: 0 | AB26: 0 | AC26: 0 | AD26: 0 | AE26: 0
S27: 0 | T27: 0 | U27: 0 | V27: 0 | W27: 0 | X27: 0 | Y27: 0 | Z27: 0 | AB27: 0 | AC27: 0 | AD27: 0 | AE27: 0
S28: 0 | T28: 0 | U28: 0 | V28: 0 | W28: 0 | X28: 0 | Y28: 0 | Z28: 0 | AB28: 0 | AC28: 0 | AD28: 0 | AE28: 0
... S41: 0 | T41: 0 | U41: 0 | V41: 0 | W41: 0 | X41: 0 | Y41: 0 | Z41: 0 | AB41: 0 | AC41: 0 | AD41: 0 | AE41: 0
AB42: 0 | AC42: 0
S43: =SUM(S17:S42) -> 0 | T43: =SUM(T17:T42) -> 0 | U43: =SUM(U17:U42) -> 0 | V43: =SUM(V17:V42) -> 0 | W43: =SUM(W17:W42) -> 0 | X43: =SUM(X17:X42) -> 0 | Y43: =SUM(Y17:Y42) -> 0 | Z43: =SUM(Z17:Z42) -> 0 | AB43: =SUM(AB17:AB42) -> 0 | AC43: =SUM(AC17:AC42) -> 0 | AD43: =SUM(AD17:AD42) -> 0 | AE43: =SUM(AE17:AE42) -> 0
S44: =S43*11 -> 0 | T44: =T43*66 -> 0 | U44: =U43*11 -> 0 | V44: =V43*66 -> 0 | W44: =W43*11 -> 0 | X44: =X43*66 -> 0 | Y44: =Y43*11 -> 0 | Z44: =Z43*66 -> 0 | AB44: =AB43*11 -> 0 | AC44: =AC43*66 -> 0 | AD44: =AD43*11 -> 0 | AE44: =AE43*66 -> 0
S45: 2nd Floor
S46: East | U46: West | W46: North | Y46: South | AB46: Virtually Dirty Totes | AD46: Damaged Totes
S47: 1 | U47: 2 | W47: 3 | Y47: 4 | AB47: Second Floor | AD47: Second Floor
S48: S | T48: P | U48: S | V48: P | W48: S | X48: P | Y48: S | Z48: P | AB48: S | AC48: P | AD48: S | AE48: P
S49: 0 | T49: 0 | U49: 0 | V49: 0 | W49: 0 | X49: 0 | Y49: 0 | Z49: 0 | AB49: 0 | AC49: 0 | AD49: 0 | AE49: 0
S50: 0 | T50: 0 | U50: 0 | V50: 0 | W50: 0 | X50: 0 | Y50: 0 | Z50: 0 | AB50: 0 | AC50: 0 | AD50: 0 | AE50: 0
S51: 0 | T51: 0 | U51: 0 | V51: 0 | W51: 0 | X51: 0 | Y51: 0 | Z51: 0 | AB51: 0 | AC51: 0 | AD51: 0 | AE51: 0
S52: 0 | T52: 0 | U52: 0 | V52: 0 | W52: 0 | X52: 0 | Y52: 0 | Z52: 0 | AB52: 0 | AC52: 0 | AD52: 0 | AE52: 0
S53: 0 | T53: 0 | U53: 0 | V53: 0 | W53: 0 | X53: 0 | Y53: 0 | Z53: 0 | AB53: 0 | AC53: 0 | AD53: 0 | AE53: 0
S54: 0 | T54: 0 | U54: 0 | V54: 0 | W54: 0 | X54: 0 | Y54: 0 | Z54: 0 | AB54: 0 | AC54: 0 | AD54: 0 | AE54: 0
S55: 0 | T55: 0 | U55: 0 | V55: 0 | W55: 0 | X55: 0 | Y55: 0 | Z55: 0 | AB55: 0 | AC55: 0 | AD55: 0 | AE55: 0
...

Sheet Quick View
A1: HOU6 TOTE DASHBOARD — QUICK VIEW
A2: Live data — auto-updates from Tote Count Entry & Demand Calculator
A4: Total Totes | B4: Usable Totes | C4: Damaged | D4: VDT | E4: Shift Demand | F4: Building Status
A5: ='Tote Count Entry'!C10 -> 0 | B5: ='Tote Count Entry'!D10 -> 0 | C5: ='Tote Count Entry'!J10 -> 0 | D5: ='Tote Count Entry'!I10 -> 0 | E5: ='Demand Calculator'!B10 -> 0 | F5: ='Demand Calculator'!B26 -> REDISTRIBUTE - Building has 0 surplus totes (0 pallets). Move to pick areas.
A7: FLOOR STATUS
A8: Floor | B8: Usable Totes | C8: Shift Demand | D8: Surplus / Deficit | E8: Pallets +/- | F8: Prescription
A9: 1st Floor | B9: ='Building Overview'!C4 -> 0 | C9: =0 -> 0 | D9: =B9-C9 -> 0 | E9: =CEILING(ABS(D9)/66,1) -> 0 | F9: ='Building Overview'!G4 -> ON TARGET
A10: 2nd Floor | B10: ='Building Overview'!C10 -> 0 | C10: ='Building Overview'!E10 -> 0 | D10: =B10-C10 -> 0 | E10: =IF(D10>=0,CEILING(D10/66,1),-CEILING(ABS(D10)/66,1)) -> 0 | F10: ='Building Overview'!G10 -> REDISTRIBUTE 0 totes to WEST (0 pallets avail)
A11: 3rd Floor | B11: ='Building Overview'!C15 -> 0 | C11: ='Building Overview'!E15 -> 0 | D11: =B11-C11 -> 0 | E11: =IF(D11>=0,CEILING(D11/66,1),-CEILING(ABS(D11)/66,1)) -> 0 | F11: ='Building Overview'!G15 -> REDISTRIBUTE 0 totes to WEST (0 pallets avail)
A12: 4th Floor | B12: ='Building Overview'!C20 -> 0 | C12: ='Building Overview'!E20 -> 0 | D12: =B12-C12 -> 0 | E12: =IF(D12>=0,CEILING(D12/66,1),-CEILING(ABS(D12)/66,1)) -> 0 | F12: ='Building Overview'!G20 -> REDISTRIBUTE 0 totes to WEST (0 pallets avail)
A13: 5th Floor | B13: ='Building Overview'!C23 -> 0 | C13: ='Building Overview'!E23 -> 0 | D13: =B13-C13 -> 0 | E13: =IF(D13>=0,CEILING(D13/66,1),-CEILING(ABS(D13)/66,1)) -> 0 | F13: ='Building Overview'!G23 -> REDISTRIBUTE within floor - 0 tote surplus (0 pallets)
A14: BUILDING TOTAL | B14: =SUM(B9:B13) -> 0 | C14: =SUM(C9:C13) -> 0 | D14: =B14-C14 -> 0 | E14: =IF(D14>=0,CEILING(D14/66,1),-CEILING(ABS(D14)/66,1)) -> 0 | F14: ='Building Overview'!G24 -> BUILDING OK - REDISTRIBUTE (0 tote surplus, 0 pallets)
A16: 1ST FLOOR REDISTRIBUTION
A17: Send To | B17: Totes to Send | C17: Pallets to Move | D17: Remaining Shortfall | E17: Status
A18: 3rd Floor | B18: ='Building Overview'!C32 -> 0 | C18: ='Building Overview'!D32 -> 0 | D18: ='Building Overview'!E32 -> 0 | E18: ='Building Overview'!G32 -> COVERED by 1st Floor
A19: 4th Floor | B19: ='Building Overview'!C33 -> 0 | C19: ='Building Overview'!D33 -> 0 | D19: ='Building Overview'!E33 -> 0 | E19: ='Building Overview'!G33 -> COVERED by 1st Floor
A20: TOTAL | B20: =SUM(B18:B19) -> 0 | C20: =SUM(C18:C19) -> 0 | D20: =SUM(D18:D19) -> 0 | E20: =IF(D20>=0,"All deficits covered","ADD "&CEILING(ABS(D20)/66,1)&" pallets from outside") -> All deficits covered
A22: ACTION STEPS
A23: Step | B23: Action
A24: 1 | B24: =IF('Building Overview'!C32>0,"Move "&'Building Overview'!D32&" pallets ("&'Building Overview'!C32&" totes) from 1st Floor to 3rd Floor WEST","3rd Floor does not need 1st Floor totes") -> 3rd Floor does not need 1st Floor totes
A25: 2 | B25: =IF('Building Overview'!C33>0,"Move "&'Building Overview'!D33&" pallets ("&'Building Overview'!C33&" totes) from 1st Floor to 4th Floor WEST","4th Floor does not need 1st Floor totes") -> 4th Floor does not need 1st Floor totes
A26: 3 | B26: =IF('Building Overview'!F10>=0,"2nd Floor: Move totes from EAST/NORTH/SOUTH to WEST ("&('Building Overview'!C6+'Building Overview'!C8+'Building Overview'!C9)&" totes, "&CEILING(('Building Overview'!C6+'Building Overview'!C8+'Building Overview'!C9)/66,1)&" pallets available)","2nd Floor: Move all non-WEST totes to WEST + bring in more") -> 2nd Floor: Move totes from EAST/NORTH/SOUTH to WEST (0 totes, 0 pallets available)
A27: 4 | B27: =IF('Building Overview'!F23>=0,"5th Floor: Move "&CEILING(ABS('Building Overview'!F22)/66,1)&" pallets from EAST to WEST ("&ABS('Building Overview'!F22)&" totes)","5th Floor: Move all EAST totes to WEST + bring in more") -> 5th Floor: Move 0 pallets from EAST to WEST (0 totes)
A28: 5 | B28: =IF(D20<0,"Bring in "&CEILING(ABS(D20)/66,1)&" pallets from outside the building ("&ABS(D20)&" totes short after redistribution)","No outside pallets needed — redistribute only!") -> No outside pallets needed — redistribute only!
A30: Created by Hayden Gruppi (gruphaym) | Do not distribute without permission

Sheet Building Overview
A1: HOU6 BUILDING OVERVIEW
A2: Auto-populated from Tote Count Entry + Demand Calculator | I2: HOURLY VIEW (1-Hour Basis)
A3: Floor | B3: Area | C3: Usable Totes | D3: Pallets Equiv | E3: Totes Needed (Shift) | F3: Surplus / Deficit | G3: Prescription | I3: Totes/Hr | J3: Hrs Sustainable | K3: Hourly Surplus / Deficit | L3: Hourly Rx (1 Hr) | M3: EAST Covers WEST (Hrs)
A4: 1st Floor | B4: All Areas | C4: ='Tote Count Entry'!E5+'Tote Count Entry'!F5+'Tote Count Entry'!G5+'Tote Count Entry'!H5 -> 0 | D4: =CEILING(C4/66,1) -> 0 | E4: 0 | F4: =C4-E4 -> 0 | G4: =IF(F4>0,"REMOVE "&CEILING(F4/66,1)&" pallets — Send "&C32&" to 3rd Flr ("&D32&" pallets) + "&C33&" to 4th Flr ("&D33&" pallets)","ON TARGET") -> ON TARGET | I4: N/A | J4: N/A | K4: N/A | L4: N/A | M4: N/A
A6: 2nd Floor | B6: EAST | C6: ='Tote Count Entry'!E6 -> 0 | D6: =CEILING(C6/66,1) -> 0 | E6: 0 | F6: =C6-E6 -> 0 | G6: =IF(F6>0,CONCATENATE(F6," totes available (",CEILING(F6/66,1)," pallets)"),"—") -> — | I6: 0 | J6: — | K6: — | L6: =IF(C6>0,CONCATENATE(C6," totes available (",CEILING(C6/66,1)," pallets)"),"—") -> — | M6: =IF('Demand Calculator'!D35=0,"—",ROUND(C6/'Demand Calculator'!D35,1)&" hrs") -> —
B7: WEST | C7: ='Tote Count Entry'!F6 -> 0 | D7: =CEILING(C7/66,1) -> 0 | E7: ='Demand Calculator'!E35 -> 0 | F7: =C7-E7 -> 0 | G7: =IF(F7>0,CONCATENATE("REMOVE ",CEILING(F7/66,1)," pallets"),IF(F7<0,CONCATENATE("ADD ",CEILING(ABS(F7)/66,1)," pallets"),"ON TARGET")) -> ON TARGET | I7: ='Demand Calculator'!D35 -> 0 | J7: =IF(I7=0,"—",ROUND(C7/I7,1)) -> — | K7: =C7-I7 -> 0 | L7: =IF(K7>0,CONCATENATE("REMOVE ",CEILING(K7/66,1)," pallets"),IF(K7<0,CONCATENATE("ADD ",CEILING(ABS(K7)/66,1)," pallets"),"ON TARGET")) -> ON TARGET | M7: —
B8: NORTH | C8: ='Tote Count Entry'!G6 -> 0 | D8: =CEILING(C8/66,1) -> 0 | E8: — | F8: — | G8: — | I8: — | J8: — | K8: — | L8: — | M8: —
B9: SOUTH | C9: ='Tote Count Entry'!H6 -> 0 | D9: =CEILING(C9/66,1) -> 0 | E9: — | F9: — | G9: — | I9: — | J9: — | K9: — | L9: — | M9: —
B10: FLOOR TOTAL | C10: =SUM(C6:C9) -> 0 | D10: =CEILING(C10/66,1) -> 0 | E10: =E7 -> 0 | F10: =C10-E10 -> 0 | G10: =IF(F10>=0,"REDISTRIBUTE "&(C6+C8+C9)&" totes to WEST ("&CEILING((C6+C8+C9)/66,1)&" pallets avail)","MOVE all "&(C6+C8+C9)&" to WEST + ADD "&CEILING(ABS(F10+(C6+C8+C9))/66,1)&" pallets") -> REDISTRIBUTE 0 totes to WEST (0 pallets avail)
A11: 3rd Floor | B11: EAST | C11: ='Tote Count Entry'!E7 -> 0 | D11: =CEILING(C11/66,1) -> 0 | E11: 0 | F11: =C11-E11 -> 0 | G11: =IF(F11>0,CONCATENATE(F11," totes available (",CEILING(F11/66,1)," pallets)"),"—") -> — | I11: 0 | J11: — | K11: — | L11: =IF(C11>0,CONCATENATE(C11," totes available (",CEILING(C11/66,1)," pallets)"),"—") -> — | M11: =IF('Demand Calculator'!D36=0,"—",ROUND(C11/'Demand Calculator'!D36,1)&" hrs") -> —
B12: WEST | C12: ='Tote Count Entry'!F7 -> 0 | D12: =CEILING(C12/66,1) -> 0 | E12: ='Demand Calculator'!E36 -> 0 | F12: =C12-E12 -> 0 | G12: =IF(F12>0,CONCATENATE("REMOVE ",CEILING(F12/66,1)," pallets"),IF(F12<0,CONCATENATE("ADD ",CEILING(ABS(F12)/66,1)," pallets"),"ON TARGET")) -> ON TARGET | I12: ='Demand Calculator'!D36 -> 0 | J12: =IF(I12=0,"—",ROUND(C12/I12,1)) -> — | K12: =C12-I12 -> 0 | L12: =IF(K12>0,CONCATENATE("REMOVE ",CEILING(K12/66,1)," pallets"),IF(K12<0,CONCATENATE("ADD ",CEILING(ABS(K12)/66,1)," pallets"),"ON TARGET")) -> ON TARGET | M12: —
B13: NORTH | C13: ='Tote Count Entry'!G7 -> 0 | D13: =CEILING(C13/66,1) -> 0 | E13: — | F13: — | G13: — | I13: — | J13: — | K13: — | L13: — | M13: —
B14: SOUTH | C14: ='Tote Count Entry'!H7 -> 0 | D14: =CEILING(C14/66,1) -> 0 | E14: — | F14: — | G14: — | I14: — | J14: — | K14: — | L14: — | M14: —
B15: FLOOR TOTAL | C15: =SUM(C11:C14) -> 0 | D15: =CEILING(C15/66,1) -> 0 | E15: =E12 -> 0 | F15: =C15-E15 -> 0 | G15: =IF(F15>=0,"REDISTRIBUTE "&(C11+C13+C14)&" totes to WEST ("&CEILING((C11+C13+C14)/66,1)&" pallets avail)","MOVE all "&(C11+C13+C14)&" to WEST + ADD "&CEILING(ABS(F15+(C11+C13+C14))/66,1)&" pallets") -> REDISTRIBUTE 0 totes to WEST (0 pallets avail)
A16: 4th Floor | B16: EAST | C16: ='Tote Count Entry'!E8 -> 0 | D16: =CEILING(C16/66,1) -> 0 | E16: 0 | F16: =C16-E16 -> 0 | G16: =IF(F16>0,CONCATENATE(F16," totes available (",CEILING(F16/66,1)," pallets)"),"—") -> — | I16: 0 | J16: — | K16: — | L16: =IF(C16>0,CONCATENATE(C16," totes available (",CEILING(C16/66,1)," pallets)"),"—") -> — | M16: =IF('Demand Calculator'!D37=0,"—",ROUND(C16/'Demand Calculator'!D37,1)&" hrs") -> —
B17: WEST | C17: ='Tote Count Entry'!F8 -> 0 | D17: =CEILING(C17/66,1) -> 0 | E17: ='Demand Calculator'!E37 -> 0 | F17: =C17-E17 -> 0 | G17: =IF(F17>0,CONCATENATE("REMOVE ",CEILING(F17/66,1)," pallets"),IF(F17<0,CONCATENATE("ADD ",CEILING(ABS(F17)/66,1)," pallets"),"ON TARGET")) -> ON TARGET | I17: ='Demand Calculator'!D37 -> 0 | J17: =IF(I17=0,"—",ROUND(C17/I17,1)) -> — | K17: =C17-I17 -> 0 | L17: =IF(K17>0,CONCATENATE("REMOVE ",CEILING(K17/66,1)," pallets"),IF(K17<0,CONCATENATE("ADD ",CEILING(ABS(K17)/66,1)," pallets"),"ON TARGET")) -> ON TARGET | M17: —
B18: NORTH | C18: ='Tote Count Entry'!G8 -> 0 | D18: =CEILING(C18/66,1) -> 0 | E18: — | F18: — | G18: — | I18: — | J18: — | K18: — | L18: — | M18: —
B19: SOUTH | C19: ='Tote Count Entry'!H8 -> 0 | D19: =CEILING(C19/66,1) -> 0 | E19: — | F19: — | G19: — | I19: — | J19: — | K19: — | L19: — | M19: —
B20: FLOOR TOTAL | C20: =SUM(C16:C19) -> 0 | D20: =CEILING(C20/66,1) -> 0 | E20: =E17 -> 0 | F20: =C20-E20 -> 0 | G20: =IF(F20>=0,"REDISTRIBUTE "&(C16+C18+C19)&" totes to WEST ("&CEILING((C16+C18+C19)/66,1)&" pallets avail)","MOVE all "&(C16+C18+C19)&" to WEST + ADD "&CEILING(ABS(F20+(C16+C18+C19))/66,1)&" pallets") -> REDISTRIBUTE 0 totes to WEST (0 pallets avail)
A21: 5th Floor | B21: EAST | C21: ='Tote Count Entry'!E9 -> 0 | D21: =CEILING(C21/66,1) -> 0 | E21: ='Demand Calculator'!E38 -> 0 | F21: =C21-E21 -> 0 | G21: =IF(F21>0,CONCATENATE("REMOVE ",CEILING(F21/66,1)," pallets"),IF(F21<0,CONCATENATE("ADD ",CEILING(ABS(F21)/66,1)," pallets"),"ON TARGET")) -> ON TARGET | I21: ='Demand Calculator'!D38 -> 0 | J21: =IF(I21=0,"—",ROUND(C21/I21,1)) -> — | K21: =C21-I21 -> 0 | L21: =IF(K21>0,CONCATENATE("REMOVE ",CEILING(K21/66,1)," pallets"),IF(K21<0,CONCATENATE("ADD ",CEILING(ABS(K21)/66,1)," pallets"),"ON TARGET")) -> ON TARGET | M21: =IF('Demand Calculator'!D39=0,"—",ROUND(C21/'Demand Calculator'!D39,1)&" hrs") -> —
B22: WEST | C22: ='Tote Count Entry'!F9 -> 0 | D22: =CEILING(C22/66,1) -> 0 | E22: ='Demand Calculator'!E39 -> 0 | F22: =C22-E22 -> 0 | G22: =IF(F22>0,CONCATENATE("REMOVE ",CEILING(F22/66,1)," pallets"),IF(F22<0,CONCATENATE("ADD ",CEILING(ABS(F22)/66,1)," pallets"),"ON TARGET")) -> ON TARGET | I22: ='Demand Calculator'!D39 -> 0 | J22: =IF(I22=0,"—",ROUND(C22/I22,1)) -> — | K22: =C22-I22 -> 0 | L22: =IF(K22>0,CONCATENATE("REMOVE ",CEILING(K22/66,1)," pallets"),IF(K22<0,CONCATENATE("ADD ",CEILING(ABS(K22)/66,1)," pallets"),"ON TARGET")) -> ON TARGET | M22: —
B23: FLOOR TOTAL | C23: =SUM(C21:C22) -> 0 | D23: =CEILING(C23/66,1) -> 0 | E23: =E21+E22 -> 0 | F23: =C23-E23 -> 0 | G23: =IF(F23>=0,"REDISTRIBUTE within floor - "&F23&" tote surplus ("&CEILING(F23/66,1)&" pallets)","ADD "&CEILING(ABS(F23)/66,1)&" pallets to 5th floor") -> REDISTRIBUTE within floor - 0 tote surplus (0 pallets)
A24: BUILDING TOTAL | C24: =C4+C6+C7+C8+C9+C11+C12+C13+C14+C16+C17+C18+C19+C21+C22 -> 0 | D24: =CEILING(C24/66,1) -> 0 | E24: =E7+E12+E17+E21+E22 -> 0 | F24: =C24-E24 -> 0 | G24: =IF(F24>=0,"BUILDING OK - REDISTRIBUTE ("&F24&" tote surplus, "&CEILING(F24/66,1)&" pallets)","ADD "&CEILING(ABS(F24)/66,1)&" pallets to building + REDISTRIBUTE") -> BUILDING OK - REDISTRIBUTE (0 tote surplus, 0 pallets) | I24: =I7+I12+I17+I21+I22 -> 0 | K24: =K7+K12+K17+K21+K22 -> 0
A28: 1ST FLOOR REDISTRIBUTION PLAN
A29: 1st Floor totes have no pick demand — redistribute to deficit floors
A31: Floor | B31: Current Deficit | C31: 1st Floor Allocation | D31: Pallets to Move | E31: Remaining Deficit | F31: Remaining Pallets Needed | G31: Status
A32: 3rd Floor | B32: =F15 -> 0 | C32: =IF(F15>=0,0,IF(F15+F20>=0,0,ROUND(C4*ABS(F15)/(ABS(IF(F15<0,F15,0))+ABS(IF(F20<0,F20,0))),0))) -> 0 | D32: =IF(C32=0,0,CEILING(C32/66,1)) -> 0 | E32: =B32+C32 -> 0 | F32: =IF(E32<0,CEILING(ABS(E32)/66,1),0) -> 0 | G32: =IF(E32>=0,"COVERED by 1st Floor","ADD "&F32&" more pallets from outside") -> COVERED by 1st Floor
A33: 4th Floor | B33: =F20 -> 0 | C33: =IF(F20>=0,0,IF(F15+F20>=0,0,ROUND(C4*ABS(F20)/(ABS(IF(F15<0,F15,0))+ABS(IF(F20<0,F20,0))),0))) -> 0 | D33: =IF(C33=0,0,CEILING(C33/66,1)) -> 0 | E33: =B33+C33 -> 0 | F33: =IF(E33<0,CEILING(ABS(E33)/66,1),0) -> 0 | G33: =IF(E33>=0,"COVERED by 1st Floor","ADD "&F33&" more pallets from outside") -> COVERED by 1st Floor
A35: SUMMARY
A36: 1st Floor Available | B36: =C4 -> 0 | C36: Total Allocated | D36: =C32+C33 -> 0 | E36: Remaining on 1st Floor | F36: =C4-(C32+C33) -> 0 | G36: =IF(F36>0,CEILING(F36/66,1)&" pallets stay on 1st Floor","All totes redistributed") -> All totes redistributed
A38: Created by Hayden Gruppi (gruphaym) | Do not distribute without permission

Sheet Demand Calculator
A1: HOU6 TOTE DEMAND CALCULATOR
A2: Enter values in yellow cells. Results flow to Building Overview.
A3: VARIABLE INPUTS | D3: FORMULA BREAKDOWN
A4: Number of Active Pickers
A5: Pick Rate (UPH per picker) | D5: Example | E5: 30 x 300 / 8 = 1,125 totes/hr
A6: Avg Units Per Tote | B6: 8 | D6: Totes/Shift | E6: Totes/Hr x Shift Length
A7: Shift Length (hours) | B7: 10.5 | D7: Example | E7: 1,125 x 10.5 = 11,813 totes
A8: CALCULATED RESULTS | D8: Pallets | E8: Totes/Shift / 66 (totes per pallet)
A9: Totes Consumed Per Hour | B9: =IF(B6=0,0,(B4*B5)/B6) -> 0 | D9: Stacks | E9: Totes/Shift / 11 (totes per stack)
A10: Totes Consumed Per Shift | B10: =B9*B7 -> 0
A11: Pallets Needed Per Shift | B11: =CEILING(B10/66,1) -> 0 | D11: HOW PRESCRIPTIONS WORK
A12: Stacks Needed Per Shift | B12: =CEILING(B10/11,1) -> 0 | D12: If Floor Usable > Totes Needed: | E12: REMOVE excess pallets
D13: If Floor Usable < Totes Needed: | E13: ADD needed pallets
A14: CONSTANTS (FIXED) | D14: Pallets to move | E14: ABS(Surplus or Deficit) / 66
A15: Totes Per Stack | B15: 11
A16: Stacks Per Pallet | B16: 6
A17: Totes Per Pallet | B17: =B15*B16 -> 66
A19: BUILDING SNAPSHOT (from Tote Count Entry)
A20: Building Total Totes | B20: ='Tote Count Entry'!C10 -> 0
A21: Building Usable Totes | B21: ='Tote Count Entry'!D10 -> 0
A22: Building VDT | B22: ='Tote Count Entry'!I10 -> 0
A23: Building Damaged | B23: ='Tote Count Entry'!J10 -> 0
A24: Building Pallets Equivalent | B24: =CEILING('Tote Count Entry'!D10/66,1) -> 0
A25: Building Surplus/Deficit vs Demand | B25: ='Building Overview'!C24-'Building Overview'!E24 -> 0
A26: Building Prescription | B26: =IF(B25>=0,"REDISTRIBUTE - Building has "&B25&" surplus totes ("&CEILING(B25/66,1)&" pallets). Move to pick areas.","ADD "&CEILING(ABS(B25)/66,1)&" pallets to building + REDISTRIBUTE existing totes") -> REDISTRIBUTE - Building has 0 surplus totes (0 pallets). Move to pick areas.
A28: PER-FLOOR HEADCOUNT & TOTES NEEDED
A29: Total Active Pickers (from above) | B29: =B4 -> 0
A30: Pick Rate (UPH per picker) | B30: =B5 -> 0
A31: Avg Units Per Tote | B31: =B6 -> 8
A32: Shift Length (hours) | B32: =B7 -> 10.5
A34: Floor | B34: Headcount | C34: Pick Rate (UPH) | D34: Totes/Hr | E34: Totes Needed (Shift)
A35: 2nd Floor - WEST | C35: =B30 -> 0 | D35: =IF($B$31=0,0,(B35*C35)/$B$31) -> 0 | E35: =D35*$B$32 -> 0
A36: 3rd Floor - WEST | C36: =B30 -> 0 | D36: =IF($B$31=0,0,(B36*C36)/$B$31) -> 0 | E36: =D36*$B$32 -> 0
A37: 4th Floor - WEST | C37: =B30 -> 0 | D37: =IF($B$31=0,0,(B37*C37)/$B$31) -> 0 | E37: =D37*$B$32 -> 0
A38: 5th Floor - EAST | C38: =B30 -> 0 | D38: =IF($B$31=0,0,(B38*C38)/$B$31) -> 0 | E38: =D38*$B$32 -> 0
A39: 5th Floor - WEST | C39: =B30 -> 0 | D39: =IF($B$31=0,0,(B39*C39)/$B$31) -> 0 | E39: =D39*$B$32 -> 0
A40: TOTAL | B40: =SUM(B35:B39) -> 0 | D40: =SUM(D35:D39) -> 0 | E40: =SUM(E35:E39) -> 0
A42: Created by Hayden Gruppi (gruphaym) | Do not distribute without permission

Sheet Historical Data
A1: Date | B1: DOW | C1: Floor | D1: EAST | E1: WEST | F1: NORTH | G1: SOUTH | H1: Damaged | I1: Virtually Dirty | J1: EAST P | K1: EAST S | L1: NORTH P | M1: NORTH S | N1: WEST P | O1: WEST S | P1: SOUTH P | Q1: SOUTH S | R1: VDT P | S1: VDT S | T1: Damaged P | U1: Damaged S
A2: =TODAY() -> 46292 | B2: =TEXT(A2,"dddd") -> Sunday | C2: 1st | D2: ='Tote Count Entry'!E5 -> 0 | E2: ='Tote Count Entry'!F5 -> 0 | F2: ='Tote Count Entry'!G5 -> 0 | G2: ='Tote Count Entry'!H5 -> 0 | H2: ='Tote Count Entry'!J5 -> 0 | I2: ='Tote Count Entry'!I5 -> 0 | J2: ='Tote Count Entry'!T43 -> 0 | K2: ='Tote Count Entry'!S43 -> 0 | L2: ='Tote Count Entry'!X43 -> 0 | M2: ='Tote Count Entry'!W43 -> 0 | N2: ='Tote Count Entry'!V43 -> 0 | O2: ='Tote Count Entry'!U43 -> 0 | P2: ='Tote Count Entry'!Z43 -> 0 | Q2: ='Tote Count Entry'!Y43 -> 0 | R2: ='Tote Count Entry'!AC43 -> 0 | S2: ='Tote Count Entry'!AB43 -> 0 | T2: ='Tote Count Entry'!AE43 -> 0 | U2: ='Tote Count Entry'!AD43 -> 0
A3: =A2 -> 46292 | B3: =TEXT(A3,"dddd") -> Sunday | C3: 2nd | D3: ='Tote Count Entry'!E6 -> 0 | E3: ='Tote Count Entry'!F6 -> 0 | F3: ='Tote Count Entry'!G6 -> 0 | G3: ='Tote Count Entry'!H6 -> 0 | H3: ='Tote Count Entry'!J6 -> 0 | I3: ='Tote Count Entry'!I6 -> 0 | J3: ='Tote Count Entry'!T76 -> 0 | K3: ='Tote Count Entry'!S76 -> 0 | L3: ='Tote Count Entry'!X76 -> 0 | M3: ='Tote Count Entry'!W76 -> 0 | N3: ='Tote Count Entry'!V76 -> 0 | O3: ='Tote Count Entry'!U76 -> 0 | P3: ='Tote Count Entry'!Z76 -> 0 | Q3: ='Tote Count Entry'!Y76 -> 0 | R3: ='Tote Count Entry'!AC76 -> 0 | S3: ='Tote Count Entry'!AB76 -> 0 | T3: ='Tote Count Entry'!AE76 -> 0 | U3: ='Tote Count Entry'!AD76 -> 0
A4: =A2 -> 46292 | B4: =TEXT(A4,"dddd") -> Sunday | C4: 3rd | D4: ='Tote Count Entry'!E7 -> 0 | E4: ='Tote Count Entry'!F7 -> 0 | F4: ='Tote Count Entry'!G7 -> 0 | G4: ='Tote Count Entry'!H7 -> 0 | H4: ='Tote Count Entry'!J7 -> 0 | I4: ='Tote Count Entry'!I7 -> 0 | J4: ='Tote Count Entry'!T108 -> 0 | K4: ='Tote Count Entry'!S108 -> 0 | L4: ='Tote Count Entry'!X108 -> 0 | M4: ='Tote Count Entry'!W108 -> 0 | N4: ='Tote Count Entry'!V108 -> 0 | O4: ='Tote Count Entry'!U108 -> 0 | P4: ='Tote Count Entry'!Z108 -> 0 | Q4: ='Tote Count Entry'!Y108 -> 0 | R4: ='Tote Count Entry'!AC108 -> 0 | S4: ='Tote Count Entry'!AB108 -> 0 | T4: ='Tote Count Entry'!AE108 -> 0 | U4: ='Tote Count Entry'!AD108 -> 0
A5: =A2 -> 46292 | B5: =TEXT(A5,"dddd") -> Sunday | C5: 4th | D5: ='Tote Count Entry'!E8 -> 0 | E5: ='Tote Count Entry'!F8 -> 0 | F5: ='Tote Count Entry'!G8 -> 0 | G5: ='Tote Count Entry'!H8 -> 0 | H5: ='Tote Count Entry'!J8 -> 0 | I5: ='Tote Count Entry'!I8 -> 0 | J5: ='Tote Count Entry'!T140 -> 0 | K5: ='Tote Count Entry'!S140 -> 0 | L5: ='Tote Count Entry'!X140 -> 0 | M5: ='Tote Count Entry'!W140 -> 0 | N5: ='Tote Count Entry'!V140 -> 0 | O5: ='Tote Count Entry'!U140 -> 0 | P5: ='Tote Count Entry'!Z140 -> 0 | Q5: ='Tote Count Entry'!Y140 -> 0 | R5: ='Tote Count Entry'!AC140 -> 0 | S5: ='Tote Count Entry'!AB140 -> 0 | T5: ='Tote Count Entry'!AE140 -> 0 | U5: ='Tote Count Entry'!AD140 -> 0
A6: =A2 -> 46292 | B6: =TEXT(A6,"dddd") -> Sunday | C6: 5th | D6: ='Tote Count Entry'!E9 -> 0 | E6: ='Tote Count Entry'!F9 -> 0 | F6: ='Tote Count Entry'!G9 -> 0 | G6: ='Tote Count Entry'!H9 -> 0 | H6: ='Tote Count Entry'!J9 -> 0 | I6: ='Tote Count Entry'!I9 -> 0 | J6: ='Tote Count Entry'!T172 -> 0 | K6: ='Tote Count Entry'!S172 -> 0 | L6: ='Tote Count Entry'!X172 -> 0 | M6: ='Tote Count Entry'!W172 -> 0 | N6: ='Tote Count Entry'!V172 -> 0 | O6: ='Tote Count Entry'!U172 -> 0 | P6: ='Tote Count Entry'!Z172 -> 0 | Q6: ='Tote Count Entry'!Y172 -> 0 | R6: ='Tote Count Entry'!AC172 -> 0 | S6: ='Tote Count Entry'!AB172 -> 0 | T6: ='Tote Count Entry'!AE172 -> 0 | U6: ='Tote Count Entry'!AD172 -> 0
A7: =TODAY() -> 46292 | B7: =TEXT(A7,"dddd") -> Sunday | C7: 1st | D7: ='Tote Count Entry'!E10 -> 0 | E7: ='Tote Count Entry'!F10 -> 0 | F7: ='Tote Count Entry'!G10 -> 0 | G7: ='Tote Count Entry'!H10 -> 0 | H7: ='Tote Count Entry'!J10 -> 0 | I7: ='Tote Count Entry'!I10 -> 0 | J7: ='Tote Count Entry'!T48 -> P | K7: ='Tote Count Entry'!S48 -> S | L7: ='Tote Count Entry'!X48 -> P | M7: ='Tote Count Entry'!W48 -> S | N7: ='Tote Count Entry'!V48 -> P | O7: ='Tote Count Entry'!U48 -> S | P7: ='Tote Count Entry'!Z48 -> P | Q7: ='Tote Count Entry'!Y48 -> S | R7: ='Tote Count Entry'!AC48 -> P | S7: ='Tote Count Entry'!AB48 -> S | T7: ='Tote Count Entry'!AE48 -> P | U7: ='Tote Count Entry'!AD48 -> S
A8: =A7 -> 46292 | B8: =TEXT(A8,"dddd") -> Sunday | C8: 2nd | D8: ='Tote Count Entry'!E11 -> 0 | E8: ='Tote Count Entry'!F11 -> 0 | F8: ='Tote Count Entry'!G11 -> 0 | G8: ='Tote Count Entry'!H11 -> 0 | H8: ='Tote Count Entry'!J11 -> 0 | I8: ='Tote Count Entry'!I11 -> 0 | J8: ='Tote Count Entry'!T81 -> P | K8: ='Tote Count Entry'!S81 -> S | L8: ='Tote Count Entry'!X81 -> P | M8: ='Tote Count Entry'!W81 -> S | N8: ='Tote Count Entry'!V81 -> P | O8: ='Tote Count Entry'!U81 -> S | P8: ='Tote Count Entry'!Z81 -> P | Q8: ='Tote Count Entry'!Y81 -> S | R8: ='Tote Count Entry'!AC81 -> P | S8: ='Tote Count Entry'!AB81 -> S | T8: ='Tote Count Entry'!AE81 -> P | U8: ='Tote Count Entry'!AD81 -> S
A9: =A7 -> 46292 | B9: =TEXT(A9,"dddd") -> Sunday | C9: 3rd | D9: ='Tote Count Entry'!E12 -> 0 | E9: ='Tote Count Entry'!F12 -> 0 | F9: ='Tote Count Entry'!G12 -> 0 | G9: ='Tote Count Entry'!H12 -> 0 | H9: ='Tote Count Entry'!J12 -> 0 | I9: ='Tote Count Entry'!I12 -> 0 | J9: ='Tote Count Entry'!T113 -> P | K9: ='Tote Count Entry'!S113 -> S | L9: ='Tote Count Entry'!X113 -> P | M9: ='Tote Count Entry'!W113 -> S | N9: ='Tote Count Entry'!V113 -> P | O9: ='Tote Count Entry'!U113 -> S | P9: ='Tote Count Entry'!Z113 -> P | Q9: ='Tote Count Entry'!Y113 -> S | R9: ='Tote Count Entry'!AC113 -> P | S9: ='Tote Count Entry'!AB113 -> S | T9: ='Tote Count Entry'!AE113 -> P | U9: ='Tote Count Entry'!AD113 -> S
A10: =A7 -> 46292 | B10: =TEXT(A10,"dddd") -> Sunday | C10: 4th | D10: ='Tote Count Entry'!E13 -> 0 | E10: ='Tote Count Entry'!F13 -> 0 | F10: ='Tote Count Entry'!G13 -> 0 | G10: ='Tote Count Entry'!H13 -> 0 | H10: ='Tote Count Entry'!J13 -> 0 | I10: ='Tote Count Entry'!I13 -> 0 | J10: ='Tote Count Entry'!T145 -> P | K10: ='Tote Count Entry'!S145 -> S | L10: ='Tote Count Entry'!X145 -> P | M10: ='Tote Count Entry'!W145 -> S | N10: ='Tote Count Entry'!V145 -> P | O10: ='Tote Count Entry'!U145 -> S | P10: ='Tote Count Entry'!Z145 -> P | Q10: ='Tote Count Entry'!Y145 -> S | R10: ='Tote Count Entry'!AC145 -> P | S10: ='Tote Count Entry'!AB145 -> S | T10: ='Tote Count Entry'!AE145 -> P | U10: ='Tote Count Entry'!AD145 -> S
A11: =A7 -> 46292 | B11: =TEXT(A11,"dddd") -> Sunday | C11: 5th | D11: ='Tote Count Entry'!E14 -> 0 | E11: ='Tote Count Entry'!F14 -> 0 | F11: ='Tote Count Entry'!G14 -> 0 | G11: ='Tote Count Entry'!H14 -> 0 | H11: ='Tote Count Entry'!J14 -> 0 | I11: ='Tote Count Entry'!I14 -> 0 | J11: ='Tote Count Entry'!T177 -> 0 | K11: ='Tote Count Entry'!S177 -> 0 | L11: ='Tote Count Entry'!X177 -> 0 | M11: ='Tote Count Entry'!W177 -> 0 | N11: ='Tote Count Entry'!V177 -> 0 | O11: ='Tote Count Entry'!U177 -> 0 | P11: ='Tote Count Entry'!Z177 -> 0 | Q11: ='Tote Count Entry'!Y177 -> 0 | R11: ='Tote Count Entry'!AC177 -> 0 | S11: ='Tote Count Entry'!AB177 -> 0 | T11: ='Tote Count Entry'!AE177 -> 0 | U11: ='Tote Count Entry'!AD177 -> 0
A73: Created by Hayden Gruppi (gruphaym) | Do not distribute without permission
